Workbook
Name Slicer_Representative1: #N/A

Sheet Data
B1: Call Centre Data
B3: Call number | C3: Customer ID | D3: Duration | E3: Representative | F3: Date of Call | G3: Purchase Amount | H3: Satisfaction Rating | I3: FY | J3: Day of week | K3: Duration Bucket | L3: Rounded Rating | N3: Customer ID | O3: Gender | P3: Age | Q3: City
B4: Call_7271 | C4: C0003 | D4: 116 | E4: R05 | F4: 44927 | G4: 128 | H4: 4.9 | I4: =IF(MONTH(Call_Centre[[#This Row],[Date of Call]])<=6, YEAR(Call_Centre[[#This Row],[Date of Call]]), YEAR(Call_Centre[[#This Row],[Date of Call]])+1) -> 2023 | J4: =TEXT(Call_Centre[[#This Row],[Date of Call]],"DDDD") -> Sunday | K4: {=_xlfn.IFS(Call_Centre[[#This Row],[Duration]]<=10,"Under 10 mins", Call_Centre[[#This Row],[Duration]]<=30, "10 to 30 mins", Call_Centre[[#This Row],[Duration]]<=60, "30 to 60 mins", Call_Centre[[#This Row],[Duration]]<=120, "1 to 2 hours", TRUE, "More than 2 hours")} -> 1 to 2 hours | L4: =ROUND(Call_Centre[[#This Row],[Satisfaction Rating]],0) -> 5 | N4: C0001 | O4: Male | P4: 41 | Q4: Columbus
B5: Call_7272 | C5: C0004 | D5: 119 | E5: R05 | F5: 44927 | G5: 135 | H5: 2.9 | I5: =IF(MONTH(Call_Centre[[#This Row],[Date of Call]])<=6, YEAR(Call_Centre[[#This Row],[Date of Call]]), YEAR(Call_Centre[[#This Row],[Date of Call]])+1) -> 2023 | J5: =TEXT(Call_Centre[[#This Row],[Date of Call]],"DDDD") -> Sunday | K5: {=_xlfn.IFS(Call_Centre[[#This Row],[Duration]]<=10,"Under 10 mins", Call_Centre[[#This Row],[Duration]]<=30, "10 to 30 mins", Call_Centre[[#This Row],[Duration]]<=60, "30 to 60 mins", Call_Centre[[#This Row],[Duration]]<=120, "1 to 2 hours", TRUE, "More than 2 hours")} -> 1 to 2 hours | L5: =ROUND(Call_Centre[[#This Row],[Satisfaction Rating]],0) -> 3 | N5: C0002 | O5: Male | P5: 31 | Q5: Cleveland
B6: Call_7273 | C6: C0005 | D6: 68 | E6: R02 | F6: 44927 | G6: 66 | H6: 4.7 | I6: =IF(MONTH(Call_Centre[[#This Row],[Date of Call]])<=6, YEAR(Call_Centre[[#This Row],[Date of Call]]), YEAR(Call_Centre[[#This Row],[Date of Call]])+1) -> 2023 | J6: =TEXT(Call_Centre[[#This Row],[Date of Call]],"DDDD") -> Sunday | K6: {=_xlfn.IFS(Call_Centre[[#This Row],[Duration]]<=10,"Under 10 mins", Call_Centre[[#This Row],[Duration]]<=30, "10 to 30 mins", Call_Centre[[#This Row],[Duration]]<=60, "30 to 60 mins", Call_Centre[[#This Row],[Duration]]<=120, "1 to 2 hours", TRUE, "More than 2 hours")} -> 1 to 2 hours | L6: =ROUND(Call_Centre[[#This Row],[Satisfaction Rating]],0) -> 5 | N6: C0003 | O6: Male | P6: 26 | Q6: Cincinnati
B7: Call_7274 | C7: C0014 | D7: 119 | E7: R02 | F7: 44927 | G7: 22 | H7: 2.9 | I7: =IF(MONTH(Call_Centre[[#This Row],[Date of Call]])<=6, YEAR(Call_Centre[[#This Row],[Date of Call]]), YEAR(Call_Centre[[#This Row],[Date of Call]])+1) -> 2023 | J7: =TEXT(Call_Centre[[#This Row],[Date of Call]],"DDDD") -> Sunday | K7: {=_xlfn.IFS(Call_Centre[[#This Row],[Duration]]<=10,"Under 10 mins", Call_Centre[[#This Row],[Duration]]<=30, "10 to 30 mins", Call_Centre[[#This Row],[Duration]]<=60, "30 to 60 mins", Call_Centre[[#This Row],[Duration]]<=120, "1 to 2 hours", TRUE, "More than 2 hours")} -> 1 to 2 hours | L7: =ROUND(Call_Centre[[#This Row],[Satisfaction Rating]],0) -> 3 | N7: C0004 | O7: Male | P7: 36 | Q7: Cincinnati
B8: Call_7275 | C8: C0011 | D8: 128 | E8: R01 | F8: 44928 | G8: 31 | H8: 2.8 | I8: =IF(MONTH(Call_Centre[[#This Row],[Date of Call]])<=6, YEAR(Call_Centre[[#This Row],[Date of Call]]), YEAR(Call_Centre[[#This Row],[Date of Call]])+1) -> 2023 | J8: =TEXT(Call_Centre[[#This Row],[Date of Call]],"DDDD") -> Monday | K8: {=_xlfn.IFS(Call_Centre[[#This Row],[Duration]]<=10,"Under 10 mins", Call_Centre[[#This Row],[Duration]]<=30, "10 to 30 mins", Call_Centre[[#This Row],[Duration]]<=60, "30 to 60 mins", Call_Centre[[#This Row],[Duration]]<=120, "1 to 2 hours", TRUE, "More than 2 hours")} -> More than 2 hours | L8: =ROUND(Call_Centre[[#This Row],[Satisfaction Rating]],0) -> 3 | N8: C0005 | O8: Male | P8: 37 | Q8: Columbus
B9: Call_7276 | C9: C0011 | D9: 49 | E9: R02 | F9: 44929 | G9: 135 | H9: 4.8 | I9: =IF(MONTH(Call_Centre[[#This Row],[Date of Call]])<=6, YEAR(Call_Centre[[#This Row],[Date of Call]]), YEAR(Call_Centre[[#This Row],[Date of Call]])+1) -> 2023 | J9: =TEXT(Call_Centre[[#This Row],[Date of Call]],"DDDD") -> Tuesday | K9: {=_xlfn.IFS(Call_Centre[[#This Row],[Duration]]<=10,"Under 10 mins", Call_Centre[[#This Row],[Duration]]<=30, "10 to 30 mins", Call_Centre[[#This Row],[Duration]]<=60, "30 to 60 mins", Call_Centre[[#This Row],[Duration]]<=120, "1 to 2 hours", TRUE, "More than 2 hours")} -> 30 to 60 mins | L9: =ROUND(Call_Centre[[#This Row],[Satisfaction Rating]],0) -> 5 | N9: C0006 | O9: Male | P9: 23 | Q9: Columbus
B10: Call_7277 | C10: C0007 | D10: 84 | E10: R05 | F10: 44929 | G10: 60 | H10: 4.7 | I10: =IF(MONTH(Call_Centre[[#This Row],[Date of Call]])<=6, YEAR(Call_Centre[[#This Row],[Date of Call]]), YEAR(Call_Centre[[#This Row],[Date of Call]])+1) -> 2023 | J10: =TEXT(Call_Centre[[#This Row],[Date of Call]],"DDDD") -> Tuesday | K10: {=_xlfn.IFS(Call_Centre[[#This Row],[Duration]]<=10,"Under 10 mins", Call_Centre[[#This Row],[Duration]]<=30, "10 to 30 mins", Call_Centre[[#This Row],[Duration]]<=60, "30 to 60 mins", Call_Centre[[#This Row],[Duration]]<=120, "1 to 2 hours", TRUE, "More than 2 hours")} -> 1 to 2 hours | L10: =ROUND(Call_Centre[[#This Row],[Satisfaction Rating]],0) -> 5 | N10: C0007 | O10: Female | P10: 22 | Q10: Cleveland
B11: Call_7278 | C11: C0003 | D11: 103 | E11: R04 | F11: 44929 | G11: 148 | H11: 4.4 | I11: =IF(MONTH(Call_Centre[[#This Row],[Date of Call]])<=6, YEAR(Call_Centre[[#This Row],[Date of Call]]), YEAR(Call_Centre[[#This Row],[Date of Call]])+1) -> 2023 | J11: =TEXT(Call_Centre[[#This Row],[Date of Call]],"DDDD") -> Tuesday | K11: {=_xlfn.IFS(Call_Centre[[#This Row],[Duration]]<=10,"Under 10 mins", Call_Centre[[#This Row],[Duration]]<=30, "10 to 30 mins", Call_Centre[[#This Row],[Duration]]<=60, "30 to 60 mins", Call_Centre[[#This Row],[Duration]]<=120, "1 to 2 hours", TRUE, "More than 2 hours")} -> 1 to 2 hours | L11: =ROUND(Call_Centre[[#This Row],[Satisfaction Rating]],0) -> 4 | N11: C0008 | O11: Female | P11: 42 | Q11: Cleveland
B12: Call_7279 | C12: C0005 | D12: 31 | E12: R02 | F12: 44929 | G12: 135 | H12: 3.6 | I12: =IF(MONTH(Call_Centre[[#This Row],[Date of Call]])<=6, YEAR(Call_Centre[[#This Row],[Date of Call]]), YEAR(Call_Centre[[#This Row],[Date of Call]])+1) -> 2023 | J12: =TEXT(Call_Centre[[#This Row],[Date of Call]],"DDDD") -> Tuesday | K12: {=_xlfn.IFS(Call_Centre[[#This Row],[Duration]]<=10,"Under 10 mins", Call_Centre[[#This Row],[Duration]]<=30, "10 to 30 mins", Call_Centre[[#This Row],[Duration]]<=60, "30 to 60 mins", Call_Centre[[#This Row],[Duration]]<=120, "1 to 2 hours", TRUE, "More than 2 hours")} -> 30 to 60 mins | L12: =ROUND(Call_Centre[[#This Row],[Satisfaction Rating]],0) -> 4 | N12: C0009 | O12: Female | P12: 25 | Q12: Columbus
B13: Call_7280 | C13: C0010 | D13: 44 | E13: R03 | F13: 44929 | G13: 105 | H13: 2.9 | I13: =IF(MONTH(Call_Centre[[#This Row],[Date of Call]])<=6, YEAR(Call_Centre[[#This Row],[Date of Call]]), YEAR(Call_Centre[[#This Row],[Date of Call]])+1) -> 2023 | J13: =TEXT(Call_Centre[[#This Row],[Date of Call]],"DDDD") -> Tuesday | K13: {=_xlfn.IFS(Call_Centre[[#This Row],[Duration]]<=10,"Under 10 mins", Call_Centre[[#This Row],[Duration]]<=30, "10 to 30 mins", Call_Centre[[#This Row],[Duration]]<=60, "30 to 60 mins", Call_Centre[[#This Row],[Duration]]<=120, "1 to 2 hours", TRUE, "More than 2 hours")} -> 30 to 60 mins | L13: =ROUND(Call_Centre[[#This Row],[Satisfaction Rating]],0) -> 3 | N13: C0010 | O13: Female | P13: 30 | Q13: Cleveland
B14: Call_7281 | C14: C0011 | D14: 102 | E14: R02 | F14: 44929 | G14: 69 | H14: 4.9 | I14: =IF(MONTH(Call_Centre[[#This Row],[Date of Call]])<=6, YEAR(Call_Centre[[#This Row],[Date of Call]]), YEAR(Call_Centre[[#This Row],[Date of Call]])+1) -> 2023 | J14: =TEXT(Call_Centre[[#This Row],[Date of Call]],"DDDD") -> Tuesday | K14: {=_xlfn.IFS(Call_Centre[[#This Row],[Duration]]<=10,"Under 10 mins", Call_Centre[[#This Row],[Duration]]<=30, "10 to 30 mins", Call_Centre[[#This Row],[Duration]]<=60, "30 to 60 mins", Call_Centre[[#This Row],[Duration]]<=120, "1 to 2 hours", TRUE, "More than 2 hours")} -> 1 to 2 hours | L14: =ROUND(Call_Centre[[#This Row],[Satisfaction Rating]],0) -> 5 | N14: C0011 | O14: Female | P14: 30 | Q14: Cincinnati
B15: Call_7282 | C15: C0013 | D15: 135 | E15: R05 | F15: 44929 | G15: 46 | H15: 3.4 | I15: =IF(MONTH(Call_Centre[[#This Row],[Date of Call]])<=6, YEAR(Call_Centre[[#This Row],[Date of Call]]), YEAR(Call_Centre[[#This Row],[Date of Call]])+1) -> 2023 | J15: =TEXT(Call_Centre[[#This Row],[Date of Call]],"DDDD") -> Tuesday | K15: {=_xlfn.IFS(Call_Centre[[#This Row],[Duration]]<=10,"Under 10 mins", Call_Centre[[#This Row],[Duration]]<=30, "10 to 30 mins", Call_Centre[[#This Row],[Duration]]<=60, "30 to 60 mins", Call_Centre[[#This Row],[Duration]]<=120, "1 to 2 hours", TRUE, "More than 2 hours")} -> More than 2 hours | L15: =ROUND(Call_Centre[[#This Row],[Satisfaction Rating]],0) -> 3 | N15: C0012 | O15: Female | P15: 28 | Q15: Cincinnati
... B18: Call_7285 | C18: C0013 | D18: 48 | E18: R01 | F18: 44930 | G18: 68 | H18: 4.9 | I18: =IF(MONTH(Call_Centre[[#This Row],[Date of Call]])<=6, YEAR(Call_Centre[[#This Row],[Date of Call]]), YEAR(Call_Centre[[#This Row],[Date of Call]])+1) -> 2023 | J18: =TEXT(Call_Centre[[#This Row],[Date of Call]],"DDDD") -> Wednesday | K18: {=_xlfn.IFS(Call_Centre[[#This Row],[Duration]]<=10,"Under 10 mins", Call_Centre[[#This Row],[Duration]]<=30, "10 to 30 mins", Call_Centre[[#This Row],[Duration]]<=60, "30 to 60 mins", Call_Centre[[#This Row],[Duration]]<=120, "1 to 2 hours", TRUE, "More than 2 hours")} -> 30 to 60 mins | L18: =ROUND(Call_Centre[[#This Row],[Satisfaction Rating]],0) -> 5 | N18: C0015 | O18: Female | P18: 43 | Q18: Cleveland
B19: Call_7286 | C19: C0010 | D19: 176 | E19: R05 | F19: 44931 | G19: 24 | H19: 4.8 | I19: =IF(MONTH(Call_Centre[[#This Row],[Date of Call]])<=6, YEAR(Call_Centre[[#This Row],[Date of Call]]), YEAR(Call_Centre[[#This Row],[Date of Call]])+1) -> 2023 | J19: =TEXT(Call_Centre[[#This Row],[Date of Call]],"DDDD") -> Thursday | K19: {=_xlfn.IFS(Call_Centre[[#This Row],[Duration]]<=10,"Under 10 mins", Call_Centre[[#This Row],[Duration]]<=30, "10 to 30 mins", Call_Centre[[#This Row],[Duration]]<=60, "30 to 60 mins", Call_Centre[[#This Row],[Duration]]<=120, "1 to 2 hours", TRUE, "More than 2 hours")} -> More than 2 hours | L19: =ROUND(Call_Centre[[#This Row],[Satisfaction Rating]],0) -> 5
B20: Call_7287 | C20: C0010 | D20: 99 | E20: R01 | F20: 44931 | G20: 195 | H20: 3.9 | I20: =IF(MONTH(Call_Centre[[#This Row],[Date of Call]])<=6, YEAR(Call_Centre[[#This Row],[Date of Call]]), YEAR(Call_Centre[[#This Row],[Date of Call]])+1) -> 2023 | J20: =TEXT(Call_Centre[[#This Row],[Date of Call]],"DDDD") -> Thursday | K20: {=_xlfn.IFS(Call_Centre[[#This Row],[Duration]]<=10,"Under 10 mins", Call_Centre[[#This Row],[Duration]]<=30, "10 to 30 mins", Call_Centre[[#This Row],[Duration]]<=60, "30 to 60 mins", Call_Centre[[#This Row],[Duration]]<=120, "1 to 2 hours", TRUE, "More than 2 hours")} -> 1 to 2 hours | L20: =ROUND(Call_Centre[[#This Row],[Satisfaction Rating]],0) -> 4
B21: Call_7288 | C21: C0009 | D21: 28 | E21: R03 | F21: 44931 | G21: 28 | H21: 3.8 | I21: =IF(MONTH(Call_Centre[[#This Row],[Date of Call]])<=6, YEAR(Call_Centre[[#This Row],[Date of Call]]), YEAR(Call_Centre[[#This Row],[Date of Call]])+1) -> 2023 | J21: =TEXT(Call_Centre[[#This Row],[Date of Call]],"DDDD") -> Thursday | K21: {=_xlfn.IFS(Call_Centre[[#This Row],[Duration]]<=10,"Under 10 mins", Call_Centre[[#This Row],[Duration]]<=30, "10 to 30 mins", Call_Centre[[#This Row],[Duration]]<=60, "30 to 60 mins", Call_Centre[[#This Row],[Duration]]<=120, "1 to 2 hours", TRUE, "More than 2 hours")} -> 10 to 30 mins | L21: =ROUND(Call_Centre[[#This Row],[Satisfaction Rating]],0) -> 4
B22: Call_7289 | C22: C0007 | D22: 54 | E22: R02 | F22: 44931 | G22: 170 | H22: 4.3 | I22: =IF(MONTH(Call_Centre[[#This Row],[Date of Call]])<=6, YEAR(Call_Centre[[#This Row],[Date of Call]]), YEAR(Call_Centre[[#This Row],[Date of Call]])+1) -> 2023 | J22: =TEXT(Call_Centre[[#This Row],[Date of Call]],"DDDD") -> Thursday | K22: {=_xlfn.IFS(Call_Centre[[#This Row],[Duration]]<=10,"Under 10 mins", Call_Centre[[#This Row],[Duration]]<=30, "10 to 30 mins", Call_Centre[[#This Row],[Duration]]<=60, "30 to 60 mins", Call_Centre[[#This Row],[Duration]]<=120, "1 to 2 hours", TRUE, "More than 2 hours")} -> 30 to 60 mins | L22: =ROUND(Call_Centre[[#This Row],[Satisfaction Rating]],0) -> 4
B23: Call_7290 | C23: C0006 | D23: 48 | E23: R05 | F23: 44932 | G23: 30 | H23: 4.4 | I23: =IF(MONTH(Call_Centre[[#This Row],[Date of Call]])<=6, YEAR(Call_Centre[[#This Row],[Date of Call]]), YEAR(Call_Centre[[#This Row],[Date of Call]])+1) -> 2023 | J23: =TEXT(Call_Centre[[#This Row],[Date of Call]],"DDDD") -> Friday | K23: {=_xlfn.IFS(Call_Centre[[#This Row],[Duration]]<=10,"Under 10 mins", Call_Centre[[#This Row],[Duration]]<=30, "10 to 30 mins", Call_Centre[[#This Row],[Duration]]<=60, "30 to 60 mins", Call_Centre[[#This Row],[Duration]]<=120, "1 to 2 hours", TRUE, "More than 2 hours")} -> 30 to 60 mins | L23: =ROUND(Call_Centre[[#This Row],[Satisfaction Rating]],0) -> 4
B24: Call_7291 | C24: C0004 | D24: 128 | E24: R05 | F24: 44932 | G24: 72 | H24: 5 | I24: =IF(MONTH(Call_Centre[[#This Row],[Date of Call]])<=6, YEAR(Call_Centre[[#This Row],[Date of Call]]), YEAR(Call_Centre[[#This Row],[Date of Call]])+1) -> 2023 | J24: =TEXT(Call_Centre[[#This Row],[Date of Call]],"DDDD") -> Friday | K24: {=_xlfn.IFS(Call_Centre[[#This Row],[Duration]]<=10,"Under 10 mins", Call_Centre[[#This Row],[Duration]]<=30, "10 to 30 mins", Call_Centre[[#This Row],[Duration]]<=60, "30 to 60 mins", Call_Centre[[#This Row],[Duration]]<=120, "1 to 2 hours", TRUE, "More than 2 hours")} -> More than 2 hours | L24: =ROUND(Call_Centre[[#This Row],[Satisfaction Rating]],0) -> 5
B25: Call_7292 | C25: C0004 | D25: 38 | E25: R04 | F25: 44933 | G25: 92 | H25: 4.9 | I25: =IF(MONTH(Call_Centre[[#This Row],[Date of Call]])<=6, YEAR(Call_Centre[[#This Row],[Date of Call]]), YEAR(Call_Centre[[#This Row],[Date of Call]])+1) -> 2023 | J25: =TEXT(Call_Centre[[#This Row],[Date of Call]],"DDDD") -> Saturday | K25: {=_xlfn.IFS(Call_Centre[[#This Row],[Duration]]<=10,"Under 10 mins", Call_Centre[[#This Row],[Duration]]<=30, "10 to 30 mins", Call_Centre[[#This Row],[Duration]]<=60, "30 to 60 mins", Call_Centre[[#This Row],[Duration]]<=120, "1 to 2 hours", TRUE, "More than 2 hours")} -> 30 to 60 mins | L25: =ROUND(Call_Centre[[#This Row],[Satisfaction Rating]],0) -> 5
B26: Call_7293 | C26: C0003 | D26: 67 | E26: R04 | F26: 44934 | G26: 165 | H26: 4.5 | I26: =IF(MONTH(Call_Centre[[#This Row],[Date of Call]])<=6, YEAR(Call_Centre[[#This Row],[Date of Call]]), YEAR(Call_Centre[[#This Row],[Date of Call]])+1) -> 2023 | J26: =TEXT(Call_Centre[[#This Row],[Date of Call]],"DDDD") -> Sunday | K26: {=_xlfn.IFS(Call_Centre[[#This Row],[Duration]]<=10,"Under 10 mins", Call_Centre[[#This Row],[Duration]]<=30, "10 to 30 mins", Call_Centre[[#This Row],[Duration]]<=60, "30 to 60 mins", Call_Centre[[#This Row],[Duration]]<=120, "1 to 2 hours", TRUE, "More than 2 hours")} -> 1 to 2 hours | L26: =ROUND(Call_Centre[[#This Row],[Satisfaction Rating]],0) -> 5
B27: Call_7294 | C27: C0015 | D27: 58 | E27: R02 | F27: 44934 | G27: 140 | H27: 2.1 | I27: =IF(MONTH(Call_Centre[[#This Row],[Date of Call]])<=6, YEAR(Call_Centre[[#This Row],[Date of Call]]), YEAR(Call_Centre[[#This Row],[Date of Call]])+1) -> 2023 | J27: =TEXT(Call_Centre[[#This Row],[Date of Call]],"DDDD") -> Sunday | K27: {=_xlfn.IFS(Call_Centre[[#This Row],[Duration]]<=10,"Under 10 mins", Call_Centre[[#This Row],[Duration]]<=30, "10 to 30 mins", Call_Centre[[#This Row],[Duration]]<=60, "30 to 60 mins", Call_Centre[[#This Row],[Duration]]<=120, "1 to 2 hours", TRUE, "More than 2 hours")} -> 30 to 60 mins | L27: =ROUND(Call_Centre[[#This Row],[Satisfaction Rating]],0) -> 2
B28: Call_7295 | C28: C0010 | D28: 54 | E28: R01 | F28: 44934 | G28: 111 | H28: 3.3 | I28: =IF(MONTH(Call_Centre[[#This Row],[Date of Call]])<=6, YEAR(Call_Centre[[#This Row],[Date of Call]]), YEAR(Call_Centre[[#This Row],[Date of Call]])+1) -> 2023 | J28: =TEXT(Call_Centre[[#This Row],[Date of Call]],"DDDD") -> Sunday | K28: {=_xlfn.IFS(Call_Centre[[#This Row],[Duration]]<=10,"Under 10 mins", Call_Centre[[#This Row],[Duration]]<=30, "10 to 30 mins", Call_Centre[[#This Row],[Duration]]<=60, "30 to 60 mins", Call_Centre[[#This Row],[Duration]]<=120, "1 to 2 hours", TRUE, "More than 2 hours")} -> 30 to 60 mins | L28: =ROUND(Call_Centre[[#This Row],[Satisfaction Rating]],0) -> 3
B29: Call_7296 | C29: C0012 | D29: 28 | E29: R05 | F29: 44935 | G29: 63 | H29: 4.1 | I29: =IF(MONTH(Call_Centre[[#This Row],[Date of Call]])<=6, YEAR(Call_Centre[[#This Row],[Date of Call]]), YEAR(Call_Centre[[#This Row],[Date of Call]])+1) -> 2023 | J29: =TEXT(Call_Centre[[#This Row],[Date of Call]],"DDDD") -> Monday | K29: {=_xlfn.IFS(Call_Centre[[#This Row],[Duration]]<=10,"Under 10 mins", Call_Centre[[#This Row],[Duration]]<=30, "10 to 30 mins", Call_Centre[[#This Row],[Duration]]<=60, "30 to 60 mins", Call_Centre[[#This Row],[Duration]]<=120, "1 to 2 hours", TRUE, "More than 2 hours")} -> 10 to 30 mins | L29: =ROUND(Call_Centre[[#This Row],[Satisfaction Rating]],0) -> 4
B30: Call_7297 | C30: C0002 | D30: 73 | E30: R05 | F30: 44935 | G30: 80 | H30: 4.2 | I30: =IF(MONTH(Call_Centre[[#This Row],[Date of Call]])<=6, YEAR(Call_Centre[[#This Row],[Date of Call]]), YEAR(Call_Centre[[#This Row],[Date of Call]])+1) -> 2023 | J30: =TEXT(Call_Centre[[#This Row],[Date of Call]],"DDDD") -> Monday | K30: {=_xlfn.IFS(Call_Centre[[#This Row],[Duration]]<=10,"Under 10 mins", Call_Centre[[#This Row],[Duration]]<=30, "10 to 30 mins", Call_Centre[[#This Row],[Duration]]<=60, "30 to 60 mins", Call_Centre[[#This Row],[Duration]]<=120, "1 to 2 hours", TRUE, "More than 2 hours")} -> 1 to 2 hours | L30: =ROUND(Call_Centre[[#This Row],[Satisfaction Rating]],0) -> 4
... B1003: Call_8270 | C1003: C0009 | D1003: 114 | E1003: R01 | F1003: 45291 | G1003: 40 | H1003: 3.9 | I1003: =IF(MONTH(Call_Centre[[#This Row],[Date of Call]])<=6, YEAR(Call_Centre[[#This Row],[Date of Call]]), YEAR(Call_Centre[[#This Row],[Date of Call]])+1) -> 2024 | J1003: =TEXT(Call_Centre[[#This Row],[Date of Call]],"DDDD") -> Sunday | K1003: {=_xlfn.IFS(Call_Centre[[#This Row],[Duration]]<=10,"Under 10 mins", Call_Centre[[#This Row],[Duration]]<=30, "10 to 30 mins", Call_Centre[[#This Row],[Duration]]<=60, "30 to 60 mins", Call_Centre[[#This Row],[Duration]]<=120, "1 to 2 hours", TRUE, "More than 2 hours")} -> 1 to 2 hours | L1003: =ROUND(Call_Centre[[#This Row],[Satisfaction Rating]],0) -> 4

Sheet Pivot Tables
A1: KPI Summary
A3: Call Count | B3: Total Amount | C3: Total Duration | D3: Avg. Rating | E3: 5* Calls
A4: 1000 | B4: 96623 | C4: 89850 | D4: 3.8854 | E4: 307
A6: KPI Summary: Selected Representative
A8: Call Count | B8: Total Amount | C8: Total Duration | D8: Avg. Rating | E8: 5* Calls
A9: 189 | B9: 18415 | C9: 16834 | D9: 3.9227513 | E9: 60
A11: Monthly Call Trend
A13: Row Labels | B13: Call Count | C13: Call Count2
A14: Jan | B14: 16 | C14: 16
A15: Feb | B15: 14 | C15: 14
A16: Mar | B16: 26 | C16: 26
A17: Apr | B17: 29 | C17: 29
A18: May | B18: 17 | C18: 17
A19: Jun | B19: 15 | C19: 15
A20: Jul | B20: 15 | C20: 15
A21: Aug | B21: 7 | C21: 7
A22: Sep | B22: 11 | C22: 11
A23: Oct | B23: 24 | C23: 24
A24: Nov | B24: 9 | C24: 9
A25: Dec | B25: 6 | C25: 6
A26: Grand Total | B26: 189 | C26: 189
A28: Weekly Call Trend
A30: Row Labels | B30: Call Count
A31: Sunday | B31: 36
A32: Monday | B32: 30
A33: Tuesday | B33: 13
A34: Wednesday | B34: 23
A35: Thursday | B35: 23
A36: Friday | B36: 24 | H36: Selected Representative(s) | I36: =A53 -> R01
A37: Saturday | B37: 40 | I37: =A54 -> 0
A38: Grand Total | B38: 189 | I38: =A55 -> 0
I39: =A56 -> 0
A40: Representative Summary | E40: Chart Data | I40: =A57 -> 0
A42: Row Labels | B42: Call Count | C42: Total Amount | E42: Rep | F42: Calls | G42: Amount | H42: Sel. Rep. Calls | I42: Sel. Rep. Amount
A43: R01 | B43: 189 | C43: 18415 | E43: {=A43:C47} -> R01 | F43: 189 | G43: 18415 | H43: =IF(COUNTIF($I$36:$I$40,E43)>0,F43,NA()) -> 189 | I43: =IF(COUNTIF($I$36:$I$40,E43)>0,G43,NA()) -> 18415
A44: R02 | B44: 218 | C44: 20581 | E44: R02 | F44: 218 | G44: 20581 | H44: =IF(COUNTIF($I$36:$I$40,E44)>0,F44,NA()) -> #N/A | I44: =IF(COUNTIF($I$36:$I$40,E44)>0,G44,NA()) -> #N/A
A45: R03 | B45: 207 | C45: 20872 | E45: R03 | F45: 207 | G45: 20872 | H45: =IF(COUNTIF($I$36:$I$40,E45)>0,F45,NA()) -> #N/A | I45: =IF(COUNTIF($I$36:$I$40,E45)>0,G45,NA()) -> #N/A
A46: R04 | B46: 186 | C46: 16651 | E46: R04 | F46: 186 | G46: 16651 | H46: =IF(COUNTIF($I$36:$I$40,E46)>0,F46,NA()) -> #N/A | I46: =IF(COUNTIF($I$36:$I$40,E46)>0,G46,NA()) -> #N/A
A47: R05 | B47: 200 | C47: 20104 | E47: R05 | F47: 200 | G47: 20104 | H47: =IF(COUNTIF($I$36:$I$40,E47)>0,F47,NA()) -> #N/A | I47: =IF(COUNTIF($I$36:$I$40,E47)>0,G47,NA()) -> #N/A
A48: Grand Total | B48: 1000 | C48: 96623
...

Sheet Customer Centre Report
Q34: Customer / City | R34: {='Pivot Tables'!B82:F82} -> R01 | S34: R02 | T34: R03 | U34: R04 | V34: R05 | W34: Total
Q35: {=IF('Pivot Tables'!A83:G100="","",'Pivot Tables'!A83:G100)} -> Cincinnati
Q36: C0003 | R36: 891 | S36: 1332 | T36: 1282 | U36: 739 | V36: 560 | W36: 4804
Q37: C0004 | R37: 1991 | S37: 1886 | T37: 1206 | U37: 884 | V37: 1722 | W37: 7689
Q38: C0011 | R38: 1163 | S38: 1180 | T38: 1616 | U38: 1043 | V38: 1747 | W38: 6749
Q39: C0012 | R39: 1438 | S39: 1616 | T39: 866 | U39: 829 | V39: 2070 | W39: 6819
Q40: Cleveland
Q41: C0002 | R41: 1233 | S41: 223 | T41: 1680 | U41: 990 | V41: 1508 | W41: 5634
Q42: C0007 | R42: 1598 | S42: 1907 | T42: 869 | U42: 1426 | V42: 1416 | W42: 7216
N43: ='Pivot Tables'!B116 -> #VALUE! | Q43: C0008 | R43: 900 | S43: 1016 | T43: 960 | U43: 940 | V43: 1193 | W43: 5009
Q44: C0010 | R44: 900 | S44: 1470 | T44: 1617 | U44: 1314 | V44: 941 | W44: 6242
Q45: C0013 | R45: 1255 | S45: 516 | T45: 1874 | U45: 1863 | V45: 1722 | W45: 7230
Q46: C0015 | R46: 1138 | S46: 1898 | T46: 1482 | U46: 846 | V46: 1154 | W46: 6518
Q47: Columbus
Q48: C0001 | R48: 1655 | S48: 805 | T48: 2263 | U48: 987 | V48: 1075 | W48: 6785
N49: ='Pivot Tables'!B111 -> % of calls: 18.90% | Q49: C0005 | R49: 1104 | S49: 2280 | T49: 1445 | U49: 1722 | V49: 1196 | W49: 7747
N50: ='Pivot Tables'!B112 -> Call rank: 4 | Q50: C0006 | R50: 372 | S50: 1818 | T50: 1346 | U50: 1156 | V50: 1484 | W50: 6176
N51: ='Pivot Tables'!B113 -> Amount rank: 4 | Q51: C0009 | R51: 1415 | S51: 1271 | T51: 1214 | U51: 1135 | V51: 1566 | W51: 6601
Q52: C0014 | R52: 1362 | S52: 1363 | T52: 1152 | U52: 777 | V52: 750 | W52: 5404

Sheet Assets
D2: Rep ID | E2: Rep Image
D3: R01 | E3: #VALUE!
D4: R02 | E4: #VALUE!
D5: R03 | E5: #VALUE!
D6: R04 | E6: #VALUE!
D7: R05 | E7: #VALUE!
D8: Multiple | E8: #VALUE!
